Workbook

Sheet DATA
A1: ID_INSPEKSI_JTM_T2 | B1: TANGGAL | C1: KOORDINAT | D1: PETUGAS | E1: UP3 | F1: ULP | G1: GARDU INDUK | H1: PENYULANG | I1: SECTION | J1: ZONA | K1: NO TIANG | L1: KONSTRUKSI | M1: ASET MENEMPEL | N1: NAMA ASET MENEMPEL | O1: METODE | P1: JENIS PERALATAN | Q1: SUHU FASA R | R1: SUHU FASA S | S1: SUHU FASA T | T1: SUHU SEKITAR (AMBIENT) | U1: HI SUTM - 1 | V1: TEMUAN LAIN | W1: JENIS PERALATAN (2) | X1: SUHU FASA R (2) | Y1: SUHU FASA S (2) | Z1: SUHU FASA T (2) | AA1: SUHU SEKITAR (AMBIENT) - 2 | AB1: HI SUTM - 2 | AC1: FOTO | AD1: FOTO TEMUAN LAIN | AE1: CATATAN | AF1: STATUS PEMELIHARAAN | AG1: TANGGAL PEMELIHARAAN | AH1: FOTO PEMELIHARAAN 1 | AI1: FOTO PEMELIHARAAN 2
A2: =IFERROR(__xludf.DUMMYFUNCTION("IMPORTRANGE(""1BXUGPQhK_7Jy6l35je9xKzSAqbY7gh5t7pnDndVjlIU"",""Sheet1!A3462:AI"")"),"4d6ebabe") -> 4d6ebabe | B2: =IFERROR(__xludf.DUMMYFUNCTION("""COMPUTED_VALUE"""),46030.82928240741) -> 46030.829 | C2: =IFERROR(__xludf.DUMMYFUNCTION("""COMPUTED_VALUE"""),"-6.899172, 107.641158") -> -6.899172, 107.641158 | D2: =IFERROR(__xludf.DUMMYFUNCTION("""COMPUTED_VALUE"""),"Sandi angga") -> Sandi angga | E2: =IFERROR(__xludf.DUMMYFUNCTION("""COMPUTED_VALUE"""),"BANDUNG") -> BANDUNG | F2: =IFERROR(__xludf.DUMMYFUNCTION("""COMPUTED_VALUE"""),"BANDUNG TIMUR") -> BANDUNG TIMUR | G2: =IFERROR(__xludf.DUMMYFUNCTION("""COMPUTED_VALUE"""),"KIARACONDONG") -> KIARACONDONG | H2: =IFERROR(__xludf.DUMMYFUNCTION("""COMPUTED_VALUE"""),"KPO") -> KPO | I2: =IFERROR(__xludf.DUMMYFUNCTION("""COMPUTED_VALUE"""),"AHN-LBS BKNA") -> AHN-LBS BKNA | J2: =IFERROR(__xludf.DUMMYFUNCTION("""COMPUTED_VALUE"""),"ZONA 2") -> ZONA 2 | K2: =IFERROR(__xludf.DUMMYFUNCTION("""COMPUTED_VALUE"""),"001") -> 001 | L2: =IFERROR(__xludf.DUMMYFUNCTION("""COMPUTED_VALUE"""),"TM - 11B/H (Kabel Naik)") -> TM - 11B/H (Kabel Naik) | M2: =IFERROR(__xludf.DUMMYFUNCTION("""COMPUTED_VALUE"""),"Tidak Ada") -> Tidak Ada | O2: =IFERROR(__xludf.DUMMYFUNCTION("""COMPUTED_VALUE"""),"PEMBANDING SEJENIS") -> PEMBANDING SEJENIS | P2: =IFERROR(__xludf.DUMMYFUNCTION("""COMPUTED_VALUE"""),"TERMINASI") -> TERMINASI | Q2: =IFERROR(__xludf.DUMMYFUNCTION("""COMPUTED_VALUE"""),24.0) -> 24 | R2: =IFERROR(__xludf.DUMMYFUNCTION("""COMPUTED_VALUE"""),24.0) -> 24 | S2: =IFERROR(__xludf.DUMMYFUNCTION("""COMPUTED_VALUE"""),23.0) -> 23 | U2: =IFERROR(__xludf.DUMMYFUNCTION("""COMPUTED_VALUE"""),"BAIK") -> BAIK | V2: =IFERROR(__xludf.DUMMYFUNCTION("""COMPUTED_VALUE"""),"Tidak Ada") -> Tidak Ada | AC2: =IFERROR(__xludf.DUMMYFUNCTION("""COMPUTED_VALUE"""),"INSPEKSI SUTM - T2_Images/4d6ebabe.FOTO.065620.jpg") -> INSPEKSI SUTM - T2_Images/4d6ebabe.FOTO.065620.jpg | AF2: =IFERROR(__xludf.DUMMYFUNCTION("""COMPUTED_VALUE"""),"BELUM") -> BELUM | AG2: =IFERROR(__xludf.DUMMYFUNCTION("""COMPUTED_VALUE"""),46030.0) -> 46030
A3: =IFERROR(__xludf.DUMMYFUNCTION("""COMPUTED_VALUE"""),"4baa5ae8") -> 4baa5ae8 | B3: =IFERROR(__xludf.DUMMYFUNCTION("""COMPUTED_VALUE"""),46030.83037037037) -> 46030.83 | C3: =IFERROR(__xludf.DUMMYFUNCTION("""COMPUTED_VALUE"""),"-6.899181, 107.641173") -> -6.899181, 107.641173 | D3: =IFERROR(__xludf.DUMMYFUNCTION("""COMPUTED_VALUE"""),"Sandi angga") -> Sandi angga | E3: =IFERROR(__xludf.DUMMYFUNCTION("""COMPUTED_VALUE"""),"BANDUNG") -> BANDUNG | F3: =IFERROR(__xludf.DUMMYFUNCTION("""COMPUTED_VALUE"""),"BANDUNG TIMUR") -> BANDUNG TIMUR | G3: =IFERROR(__xludf.DUMMYFUNCTION("""COMPUTED_VALUE"""),"KIARACONDONG") -> KIARACONDONG | H3: =IFERROR(__xludf.DUMMYFUNCTION("""COMPUTED_VALUE"""),"KPO") -> KPO | I3: =IFERROR(__xludf.DUMMYFUNCTION("""COMPUTED_VALUE"""),"AHN-LBS BKNA") -> AHN-LBS BKNA | J3: =IFERROR(__xludf.DUMMYFUNCTION("""COMPUTED_VALUE"""),"ZONA 2") -> ZONA 2 | K3: =IFERROR(__xludf.DUMMYFUNCTION("""COMPUTED_VALUE"""),"002") -> 002 | L3: =IFERROR(__xludf.DUMMYFUNCTION("""COMPUTED_VALUE"""),"TM - 8B/H (Percabangan)") -> TM - 8B/H (Percabangan) | M3: =IFERROR(__xludf.DUMMYFUNCTION("""COMPUTED_VALUE"""),"Tidak Ada") -> Tidak Ada | O3: =IFERROR(__xludf.DUMMYFUNCTION("""COMPUTED_VALUE"""),"PEMBANDING SEJENIS") -> PEMBANDING SEJENIS | P3: =IFERROR(__xludf.DUMMYFUNCTION("""COMPUTED_VALUE"""),"KONEKTOR/JUMPER") -> KONEKTOR/JUMPER | Q3: =IFERROR(__xludf.DUMMYFUNCTION("""COMPUTED_VALUE"""),21.0) -> 21 | R3: =IFERROR(__xludf.DUMMYFUNCTION("""COMPUTED_VALUE"""),22.0) -> 22 | S3: =IFERROR(__xludf.DUMMYFUNCTION("""COMPUTED_VALUE"""),23.0) -> 23 | U3: =IFERROR(__xludf.DUMMYFUNCTION("""COMPUTED_VALUE"""),"BAIK") -> BAIK | V3: =IFERROR(__xludf.DUMMYFUNCTION("""COMPUTED_VALUE"""),"Tidak Ada") -> Tidak Ada | AC3: =IFERROR(__xludf.DUMMYFUNCTION("""COMPUTED_VALUE"""),"INSPEKSI SUTM - T2_Images/4baa5ae8.FOTO.065735.jpg") -> INSPEKSI SUTM - T2_Images/4baa5ae8.FOTO.065735.jpg | AF3: =IFERROR(__xludf.DUMMYFUNCTION("""COMPUTED_VALUE"""),"BELUM") -> BELUM | AG3: =IFERROR(__xludf.DUMMYFUNCTION("""COMPUTED_VALUE"""),46030.0) -> 46030
A4: =IFERROR(__xludf.DUMMYFUNCTION("""COMPUTED_VALUE"""),"0ac7e555") -> 0ac7e555 | B4: =IFERROR(__xludf.DUMMYFUNCTION("""COMPUTED_VALUE"""),46030.83112268519) -> 46030.831 | C4: =IFERROR(__xludf.DUMMYFUNCTION("""COMPUTED_VALUE"""),"-6.899185, 107.641169") -> -6.899185, 107.641169 | D4: =IFERROR(__xludf.DUMMYFUNCTION("""COMPUTED_VALUE"""),"Sandi angga") -> Sandi angga | E4: =IFERROR(__xludf.DUMMYFUNCTION("""COMPUTED_VALUE"""),"BANDUNG") -> BANDUNG | F4: =IFERROR(__xludf.DUMMYFUNCTION("""COMPUTED_VALUE"""),"BANDUNG TIMUR") -> BANDUNG TIMUR | G4: =IFERROR(__xludf.DUMMYFUNCTION("""COMPUTED_VALUE"""),"KIARACONDONG") -> KIARACONDONG | H4: =IFERROR(__xludf.DUMMYFUNCTION("""COMPUTED_VALUE"""),"KPO") -> KPO | I4: =IFERROR(__xludf.DUMMYFUNCTION("""COMPUTED_VALUE"""),"AHN-LBS BKNA") -> AHN-LBS BKNA | J4: =IFERROR(__xludf.DUMMYFUNCTION("""COMPUTED_VALUE"""),"ZONA 2") -> ZONA 2 | K4: =IFERROR(__xludf.DUMMYFUNCTION("""COMPUTED_VALUE"""),"003") -> 003 | L4: =IFERROR(__xludf.DUMMYFUNCTION("""COMPUTED_VALUE"""),"TM - 1B/H (Tumpu)") -> TM - 1B/H (Tumpu) | M4: =IFERROR(__xludf.DUMMYFUNCTION("""COMPUTED_VALUE"""),"Tidak Ada") -> Tidak Ada | O4: =IFERROR(__xludf.DUMMYFUNCTION("""COMPUTED_VALUE"""),"PEMBANDING SEJENIS") -> PEMBANDING SEJENIS | P4: =IFERROR(__xludf.DUMMYFUNCTION("""COMPUTED_VALUE"""),"ARRESTER") -> ARRESTER | Q4: =IFERROR(__xludf.DUMMYFUNCTION("""COMPUTED_VALUE"""),23.0) -> 23 | R4: =IFERROR(__xludf.DUMMYFUNCTION("""COMPUTED_VALUE"""),23.0) -> 23 | S4: =IFERROR(__xludf.DUMMYFUNCTION("""COMPUTED_VALUE"""),23.0) -> 23 | U4: =IFERROR(__xludf.DUMMYFUNCTION("""COMPUTED_VALUE"""),"BAIK") -> BAIK | V4: =IFERROR(__xludf.DUMMYFUNCTION("""COMPUTED_VALUE"""),"Tidak Ada") -> Tidak Ada | AC4: =IFERROR(__xludf.DUMMYFUNCTION("""COMPUTED_VALUE"""),"INSPEKSI SUTM - T2_Images/0ac7e555.FOTO.065926.jpg") -> INSPEKSI SUTM - T2_Images/0ac7e555.FOTO.065926.jpg | AF4: =IFERROR(__xludf.DUMMYFUNCTION("""COMPUTED_VALUE"""),"BELUM") -> BELUM | AG4: =IFERROR(__xludf.DUMMYFUNCTION("""COMPUTED_VALUE"""),46030.0) -> 46030
A5: =IFERROR(__xludf.DUMMYFUNCTION("""COMPUTED_VALUE"""),"b36afe8f") -> b36afe8f | B5: =IFERROR(__xludf.DUMMYFUNCTION("""COMPUTED_VALUE"""),46030.83253472222) -> 46030.833 | C5: =IFERROR(__xludf.DUMMYFUNCTION("""COMPUTED_VALUE"""),"-6.899196, 107.641165") -> -6.899196, 107.641165 | D5: =IFERROR(__xludf.DUMMYFUNCTION("""COMPUTED_VALUE"""),"Sandi angga") -> Sandi angga | E5: =IFERROR(__xludf.DUMMYFUNCTION("""COMPUTED_VALUE"""),"BANDUNG") -> BANDUNG | F5: =IFERROR(__xludf.DUMMYFUNCTION("""COMPUTED_VALUE"""),"BANDUNG TIMUR") -> BANDUNG TIMUR | G5: =IFERROR(__xludf.DUMMYFUNCTION("""COMPUTED_VALUE"""),"KIARACONDONG") -> KIARACONDONG | H5: =IFERROR(__xludf.DUMMYFUNCTION("""COMPUTED_VALUE"""),"KPO") -> KPO | I5: =IFERROR(__xludf.DUMMYFUNCTION("""COMPUTED_VALUE"""),"AHN-LBS BKNA") -> AHN-LBS BKNA | J5: =IFERROR(__xludf.DUMMYFUNCTION("""COMPUTED_VALUE"""),"ZONA 2") -> ZONA 2 | K5: =IFERROR(__xludf.DUMMYFUNCTION("""COMPUTED_VALUE"""),"005") -> 005 | L5: =IFERROR(__xludf.DUMMYFUNCTION("""COMPUTED_VALUE"""),"TM - 1B/H (Tumpu)") -> TM - 1B/H (Tumpu) | M5: =IFERROR(__xludf.DUMMYFUNCTION("""COMPUTED_VALUE"""),"Tidak Ada") -> Tidak Ada | O5: =IFERROR(__xludf.DUMMYFUNCTION("""COMPUTED_VALUE"""),"PEMBANDING SEJENIS") -> PEMBANDING SEJENIS | P5: =IFERROR(__xludf.DUMMYFUNCTION("""COMPUTED_VALUE"""),"ARRESTER") -> ARRESTER | Q5: =IFERROR(__xludf.DUMMYFUNCTION("""COMPUTED_VALUE"""),23.0) -> 23 | R5: =IFERROR(__xludf.DUMMYFUNCTION("""COMPUTED_VALUE"""),24.0) -> 24 | S5: =IFERROR(__xludf.DUMMYFUNCTION("""COMPUTED_VALUE"""),23.0) -> 23 | U5: =IFERROR(__xludf.DUMMYFUNCTION("""COMPUTED_VALUE"""),"BAIK") -> BAIK | V5: =IFERROR(__xludf.DUMMYFUNCTION("""COMPUTED_VALUE"""),"Tidak Ada") -> Tidak Ada | AC5: =IFERROR(__xludf.DUMMYFUNCTION("""COMPUTED_VALUE"""),"INSPEKSI SUTM - T2_Images/b36afe8f.FOTO.070042.jpg") -> INSPEKSI SUTM - T2_Images/b36afe8f.FOTO.070042.jpg | AF5: =IFERROR(__xludf.DUMMYFUNCTION("""COMPUTED_VALUE"""),"BELUM") -> BELUM | AG5: =IFERROR(__xludf.DUMMYFUNCTION("""COMPUTED_VALUE"""),46030.0) -> 46030
A6: =IFERROR(__xludf.DUMMYFUNCTION("""COMPUTED_VALUE"""),"f4f70283") -> f4f70283 | B6: =IFERROR(__xludf.DUMMYFUNCTION("""COMPUTED_VALUE"""),46030.83445601852) -> 46030.834 | C6: =IFERROR(__xludf.DUMMYFUNCTION("""COMPUTED_VALUE"""),"-6.899181, 107.641188") -> -6.899181, 107.641188 | D6: =IFERROR(__xludf.DUMMYFUNCTION("""COMPUTED_VALUE"""),"Sandi angga") -> Sandi angga | E6: =IFERROR(__xludf.DUMMYFUNCTION("""COMPUTED_VALUE"""),"BANDUNG") -> BANDUNG | F6: =IFERROR(__xludf.DUMMYFUNCTION("""COMPUTED_VALUE"""),"BANDUNG TIMUR") -> BANDUNG TIMUR | G6: =IFERROR(__xludf.DUMMYFUNCTION("""COMPUTED_VALUE"""),"KIARACONDONG") -> KIARACONDONG | H6: =IFERROR(__xludf.DUMMYFUNCTION("""COMPUTED_VALUE"""),"KPO") -> KPO | I6: =IFERROR(__xludf.DUMMYFUNCTION("""COMPUTED_VALUE"""),"AHN-LBS BKNA") -> AHN-LBS BKNA | J6: =IFERROR(__xludf.DUMMYFUNCTION("""COMPUTED_VALUE"""),"ZONA 2") -> ZONA 2 | K6: =IFERROR(__xludf.DUMMYFUNCTION("""COMPUTED_VALUE"""),"006") -> 006 | L6: =IFERROR(__xludf.DUMMYFUNCTION("""COMPUTED_VALUE"""),"TM - 4B/H (Afspan)") -> TM - 4B/H (Afspan) | M6: =IFERROR(__xludf.DUMMYFUNCTION("""COMPUTED_VALUE"""),"Tidak Ada") -> Tidak Ada | O6: =IFERROR(__xludf.DUMMYFUNCTION("""COMPUTED_VALUE"""),"PEMBANDING SEJENIS") -> PEMBANDING SEJENIS | P6: =IFERROR(__xludf.DUMMYFUNCTION("""COMPUTED_VALUE"""),"KONEKTOR/JUMPER") -> KONEKTOR/JUMPER | Q6: =IFERROR(__xludf.DUMMYFUNCTION("""COMPUTED_VALUE"""),23.0) -> 23 | R6: =IFERROR(__xludf.DUMMYFUNCTION("""COMPUTED_VALUE"""),23.0) -> 23 | S6: =IFERROR(__xludf.DUMMYFUNCTION("""COMPUTED_VALUE"""),24.0) -> 24 | U6: =IFERROR(__xludf.DUMMYFUNCTION("""COMPUTED_VALUE"""),"BAIK") -> BAIK | V6: =IFERROR(__xludf.DUMMYFUNCTION("""COMPUTED_VALUE"""),"Tidak Ada") -> Tidak Ada | AC6: =IFERROR(__xludf.DUMMYFUNCTION("""COMPUTED_VALUE"""),"INSPEKSI SUTM - T2_Images/f4f70283.FOTO.070323.jpg") -> INSPEKSI SUTM - T2_Images/f4f70283.FOTO.070323.jpg | AF6: =IFERROR(__xludf.DUMMYFUNCTION("""COMPUTED_VALUE"""),"BELUM") -> BELUM | AG6: =IFERROR(__xludf.DUMMYFUNCTION("""COMPUTED_VALUE"""),46030.0) -> 46030
A7: =IFERROR(__xludf.DUMMYFUNCTION("""COMPUTED_VALUE"""),"b9e878ad") -> b9e878ad | B7: =IFERROR(__xludf.DUMMYFUNCTION("""COMPUTED_VALUE"""),46030.83511574074) -> 46030.835 | C7: =IFERROR(__xludf.DUMMYFUNCTION("""COMPUTED_VALUE"""),"-6.899196, 107.641191") -> -6.899196, 107.641191 | D7: =IFERROR(__xludf.DUMMYFUNCTION("""COMPUTED_VALUE"""),"Sandi angga") -> Sandi angga | E7: =IFERROR(__xludf.DUMMYFUNCTION("""COMPUTED_VALUE"""),"BANDUNG") -> BANDUNG | F7: =IFERROR(__xludf.DUMMYFUNCTION("""COMPUTED_VALUE"""),"BANDUNG TIMUR") -> BANDUNG TIMUR | G7: =IFERROR(__xludf.DUMMYFUNCTION("""COMPUTED_VALUE"""),"KIARACONDONG") -> KIARACONDONG | H7: =IFERROR(__xludf.DUMMYFUNCTION("""COMPUTED_VALUE"""),"KPO") -> KPO | I7: =IFERROR(__xludf.DUMMYFUNCTION("""COMPUTED_VALUE"""),"AHN-LBS BKNA") -> AHN-LBS BKNA | J7: =IFERROR(__xludf.DUMMYFUNCTION("""COMPUTED_VALUE"""),"ZONA 2") -> ZONA 2 | K7: =IFERROR(__xludf.DUMMYFUNCTION("""COMPUTED_VALUE"""),"012") -> 012 | L7: =IFERROR(__xludf.DUMMYFUNCTION("""COMPUTED_VALUE"""),"TM - 8B/H (Percabangan)") -> TM - 8B/H (Percabangan) | M7: =IFERROR(__xludf.DUMMYFUNCTION("""COMPUTED_VALUE"""),"Tidak Ada") -> Tidak Ada | O7: =IFERROR(__xludf.DUMMYFUNCTION("""COMPUTED_VALUE"""),"PEMBANDING SEJENIS") -> PEMBANDING SEJENIS | P7: =IFERROR(__xludf.DUMMYFUNCTION("""COMPUTED_VALUE"""),"KONEKTOR/JUMPER") -> KONEKTOR/JUMPER | Q7: =IFERROR(__xludf.DUMMYFUNCTION("""COMPUTED_VALUE"""),20.0) -> 20 | R7: =IFERROR(__xludf.DUMMYFUNCTION("""COMPUTED_VALUE"""),20.0) -> 20 | S7: =IFERROR(__xludf.DUMMYFUNCTION("""COMPUTED_VALUE"""),19.0) -> 19 | U7: =IFERROR(__xludf.DUMMYFUNCTION("""COMPUTED_VALUE"""),"BAIK") -> BAIK | V7: =IFERROR(__xludf.DUMMYFUNCTION("""COMPUTED_VALUE"""),"Tidak Ada") -> Tidak Ada | AC7: =IFERROR(__xludf.DUMMYFUNCTION("""COMPUTED_VALUE"""),"INSPEKSI SUTM - T2_Images/b9e878ad.FOTO.070425.jpg") -> INSPEKSI SUTM - T2_Images/b9e878ad.FOTO.070425.jpg | AF7: =IFERROR(__xludf.DUMMYFUNCTION("""COMPUTED_VALUE"""),"BELUM") -> BELUM | AG7: =IFERROR(__xludf.DUMMYFUNCTION("""COMPUTED_VALUE"""),46030.0) -> 46030
A8: =IFERROR(__xludf.DUMMYFUNCTION("""COMPUTED_VALUE"""),"4549d0b7") -> 4549d0b7 | B8: =IFERROR(__xludf.DUMMYFUNCTION("""COMPUTED_VALUE"""),46030.83592592592) -> 46030.836 | C8: =IFERROR(__xludf.DUMMYFUNCTION("""COMPUTED_VALUE"""),"-6.899193, 107.641196") -> -6.899193, 107.641196 | D8: =IFERROR(__xludf.DUMMYFUNCTION("""COMPUTED_VALUE"""),"Sandi angga") -> Sandi angga | E8: =IFERROR(__xludf.DUMMYFUNCTION("""COMPUTED_VALUE"""),"BANDUNG") -> BANDUNG | F8: =IFERROR(__xludf.DUMMYFUNCTION("""COMPUTED_VALUE"""),"BANDUNG TIMUR") -> BANDUNG TIMUR | G8: =IFERROR(__xludf.DUMMYFUNCTION("""COMPUTED_VALUE"""),"KIARACONDONG") -> KIARACONDONG | H8: =IFERROR(__xludf.DUMMYFUNCTION("""COMPUTED_VALUE"""),"KPO") -> KPO | I8: =IFERROR(__xludf.DUMMYFUNCTION("""COMPUTED_VALUE"""),"AHN-LBS BKNA") -> AHN-LBS BKNA | J8: =IFERROR(__xludf.DUMMYFUNCTION("""COMPUTED_VALUE"""),"ZONA 2") -> ZONA 2 | K8: =IFERROR(__xludf.DUMMYFUNCTION("""COMPUTED_VALUE"""),"014") -> 014 | L8: =IFERROR(__xludf.DUMMYFUNCTION("""COMPUTED_VALUE"""),"TM - 8B/H (Percabangan)") -> TM - 8B/H (Percabangan) | M8: =IFERROR(__xludf.DUMMYFUNCTION("""COMPUTED_VALUE"""),"Tidak Ada") -> Tidak Ada | O8: =IFERROR(__xludf.DUMMYFUNCTION("""COMPUTED_VALUE"""),"PEMBANDING SEJENIS") -> PEMBANDING SEJENIS | P8: =IFERROR(__xludf.DUMMYFUNCTION("""COMPUTED_VALUE"""),"KONEKTOR/JUMPER") -> KONEKTOR/JUMPER | Q8: =IFERROR(__xludf.DUMMYFUNCTION("""COMPUTED_VALUE"""),23.0) -> 23 | R8: =IFERROR(__xludf.DUMMYFUNCTION("""COMPUTED_VALUE"""),23.0) -> 23 | S8: =IFERROR(__xludf.DUMMYFUNCTION("""COMPUTED_VALUE"""),23.0) -> 23 | U8: =IFERROR(__xludf.DUMMYFUNCTION("""COMPUTED_VALUE"""),"BAIK") -> BAIK | V8: =IFERROR(__xludf.DUMMYFUNCTION("""COMPUTED_VALUE"""),"Tidak Ada") -> Tidak Ada | AC8: =IFERROR(__xludf.DUMMYFUNCTION("""COMPUTED_VALUE"""),"INSPEKSI SUTM - T2_Images/4549d0b7.FOTO.070617.jpg") -> INSPEKSI SUTM - T2_Images/4549d0b7.FOTO.070617.jpg | AF8: =IFERROR(__xludf.DUMMYFUNCTION("""COMPUTED_VALUE"""),"BELUM") -> BELUM | AG8: =IFERROR(__xludf.DUMMYFUNCTION("""COMPUTED_VALUE"""),46030.0) -> 46030
A9: =IFERROR(__xludf.DUMMYFUNCTION("""COMPUTED_VALUE"""),"0f9ba3b7") -> 0f9ba3b7 | B9: =IFERROR(__xludf.DUMMYFUNCTION("""COMPUTED_VALUE"""),46030.837696759256) -> 46030.838 | C9: =IFERROR(__xludf.DUMMYFUNCTION("""COMPUTED_VALUE"""),"-6.899178, 107.641207") -> -6.899178, 107.641207 | D9: =IFERROR(__xludf.DUMMYFUNCTION("""COMPUTED_VALUE"""),"Sandi angga") -> Sandi angga | E9: =IFERROR(__xludf.DUMMYFUNCTION("""COMPUTED_VALUE"""),"BANDUNG") -> BANDUNG | F9: =IFERROR(__xludf.DUMMYFUNCTION("""COMPUTED_VALUE"""),"BANDUNG TIMUR") -> BANDUNG TIMUR | G9: =IFERROR(__xludf.DUMMYFUNCTION("""COMPUTED_VALUE"""),"KIARACONDONG") -> KIARACONDONG | H9: =IFERROR(__xludf.DUMMYFUNCTION("""COMPUTED_VALUE"""),"KPO") -> KPO | I9: =IFERROR(__xludf.DUMMYFUNCTION("""COMPUTED_VALUE"""),"AHN-LBS BKNA") -> AHN-LBS BKNA | J9: =IFERROR(__xludf.DUMMYFUNCTION("""COMPUTED_VALUE"""),"ZONA 2") -> ZONA 2 | K9: =IFERROR(__xludf.DUMMYFUNCTION("""COMPUTED_VALUE"""),"014R04") -> 014R04 | L9: =IFERROR(__xludf.DUMMYFUNCTION("""COMPUTED_VALUE"""),"TM - 4B/H (Afspan)") -> TM - 4B/H (Afspan) | M9: =IFERROR(__xludf.DUMMYFUNCTION("""COMPUTED_VALUE"""),"Tidak Ada") -> Tidak Ada | O9: =IFERROR(__xludf.DUMMYFUNCTION("""COMPUTED_VALUE"""),"PEMBANDING SEJENIS") -> PEMBANDING SEJENIS | P9: =IFERROR(__xludf.DUMMYFUNCTION("""COMPUTED_VALUE"""),"KONEKTOR/JUMPER") -> KONEKTOR/JUMPER | Q9: =IFERROR(__xludf.DUMMYFUNCTION("""COMPUTED_VALUE"""),20.0) -> 20 | R9: =IFERROR(__xludf.DUMMYFUNCTION("""COMPUTED_VALUE"""),20.0) -> 20 | S9: =IFERROR(__xludf.DUMMYFUNCTION("""COMPUTED_VALUE"""),20.0) -> 20 | U9: =IFERROR(__xludf.DUMMYFUNCTION("""COMPUTED_VALUE"""),"BAIK") -> BAIK | V9: =IFERROR(__xludf.DUMMYFUNCTION("""COMPUTED_VALUE"""),"Tidak Ada") -> Tidak Ada | AC9: =IFERROR(__xludf.DUMMYFUNCTION("""COMPUTED_VALUE"""),"INSPEKSI SUTM - T2_Images/0f9ba3b7.FOTO.070808.jpg") -> INSPEKSI SUTM - T2_Images/0f9ba3b7.FOTO.070808.jpg | AF9: =IFERROR(__xludf.DUMMYFUNCTION("""COMPUTED_VALUE"""),"BELUM") -> BELUM | AG9: =IFERROR(__xludf.DUMMYFUNCTION("""COMPUTED_VALUE"""),46030.0) -> 46030
A10: =IFERROR(__xludf.DUMMYFUNCTION("""COMPUTED_VALUE"""),"2d9a7f56") -> 2d9a7f56 | B10: =IFERROR(__xludf.DUMMYFUNCTION("""COMPUTED_VALUE"""),46030.838958333334) -> 46030.839 | C10: =IFERROR(__xludf.DUMMYFUNCTION("""COMPUTED_VALUE"""),"-6.899182, 107.641199") -> -6.899182, 107.641199 | D10: =IFERROR(__xludf.DUMMYFUNCTION("""COMPUTED_VALUE"""),"Sandi angga") -> Sandi angga | E10: =IFERROR(__xludf.DUMMYFUNCTION("""COMPUTED_VALUE"""),"BANDUNG") -> BANDUNG | F10: =IFERROR(__xludf.DUMMYFUNCTION("""COMPUTED_VALUE"""),"BANDUNG TIMUR") -> BANDUNG TIMUR | G10: =IFERROR(__xludf.DUMMYFUNCTION("""COMPUTED_VALUE"""),"KIARACONDONG") -> KIARACONDONG | H10: =IFERROR(__xludf.DUMMYFUNCTION("""COMPUTED_VALUE"""),"KPO") -> KPO | I10: =IFERROR(__xludf.DUMMYFUNCTION("""COMPUTED_VALUE"""),"AHN-LBS BKNA") -> AHN-LBS BKNA | J10: =IFERROR(__xludf.DUMMYFUNCTION("""COMPUTED_VALUE"""),"ZONA 2") -> ZONA 2 | K10: =IFERROR(__xludf.DUMMYFUNCTION("""COMPUTED_VALUE"""),"017") -> 017 | L10: =IFERROR(__xludf.DUMMYFUNCTION("""COMPUTED_VALUE"""),"TM - 16B/H (REC/SSO/LBS)") -> TM - 16B/H (REC/SSO/LBS) | M10: =IFERROR(__xludf.DUMMYFUNCTION("""COMPUTED_VALUE"""),"LBS") -> LBS | N10: =IFERROR(__xludf.DUMMYFUNCTION("""COMPUTED_VALUE"""),"BKNA") -> BKNA | O10: =IFERROR(__xludf.DUMMYFUNCTION("""COMPUTED_VALUE"""),"PEMBANDING SEJENIS") -> PEMBANDING SEJENIS | P10: =IFERROR(__xludf.DUMMYFUNCTION("""COMPUTED_VALUE"""),"KONEKTOR/JUMPER") -> KONEKTOR/JUMPER | Q10: =IFERROR(__xludf.DUMMYFUNCTION("""COMPUTED_VALUE"""),22.0) -> 22 | R10: =IFERROR(__xludf.DUMMYFUNCTION("""COMPUTED_VALUE"""),21.0) -> 21 | S10: =IFERROR(__xludf.DUMMYFUNCTION("""COMPUTED_VALUE"""),21.0) -> 21 | U10: =IFERROR(__xludf.DUMMYFUNCTION("""COMPUTED_VALUE"""),"BAIK") -> BAIK | V10: =IFERROR(__xludf.DUMMYFUNCTION("""COMPUTED_VALUE"""),"Tidak Ada") -> Tidak Ada | AC10: =IFERROR(__xludf.DUMMYFUNCTION("""COMPUTED_VALUE"""),"INSPEKSI SUTM - T2_Images/2d9a7f56.FOTO.071139.jpg") -> INSPEKSI SUTM - T2_Images/2d9a7f56.FOTO.071139.jpg | AF10: =IFERROR(__xludf.DUMMYFUNCTION("""COMPUTED_VALUE"""),"BELUM") -> BELUM | AG10: =IFERROR(__xludf.DUMMYFUNCTION("""COMPUTED_VALUE"""),46030.0) -> 46030
A11: =IFERROR(__xludf.DUMMYFUNCTION("""COMPUTED_VALUE"""),"5382c293") -> 5382c293 | B11: =IFERROR(__xludf.DUMMYFUNCTION("""COMPUTED_VALUE"""),46030.84315972222) -> 46030.843 | C11: =IFERROR(__xludf.DUMMYFUNCTION("""COMPUTED_VALUE"""),"-6.899181, 107.641227") -> -6.899181, 107.641227 | D11: =IFERROR(__xludf.DUMMYFUNCTION("""COMPUTED_VALUE"""),"Sandi angga") -> Sandi angga | E11: =IFERROR(__xludf.DUMMYFUNCTION("""COMPUTED_VALUE"""),"BANDUNG") -> BANDUNG | F11: =IFERROR(__xludf.DUMMYFUNCTION("""COMPUTED_VALUE"""),"BANDUNG TIMUR") -> BANDUNG TIMUR | G11: =IFERROR(__xludf.DUMMYFUNCTION("""COMPUTED_VALUE"""),"KIARACONDONG") -> KIARACONDONG | H11: =IFERROR(__xludf.DUMMYFUNCTION("""COMPUTED_VALUE"""),"KPO") -> KPO | I11: =IFERROR(__xludf.DUMMYFUNCTION("""COMPUTED_VALUE"""),"LBS BKNA-RAT") -> LBS BKNA-RAT | J11: =IFERROR(__xludf.DUMMYFUNCTION("""COMPUTED_VALUE"""),"ZONA 2") -> ZONA 2 | K11: =IFERROR(__xludf.DUMMYFUNCTION("""COMPUTED_VALUE"""),"019") -> 019 | L11: =IFERROR(__xludf.DUMMYFUNCTION("""COMPUTED_VALUE"""),"TM - 13B/H (Kabel Naik Pada Tiang Tumpu)") -> TM - 13B/H (Kabel Naik Pada Tiang Tumpu) | M11: =IFERROR(__xludf.DUMMYFUNCTION("""COMPUTED_VALUE"""),"Tidak Ada") -> Tidak Ada | O11: =IFERROR(__xludf.DUMMYFUNCTION("""COMPUTED_VALUE"""),"PEMBANDING SEJENIS") -> PEMBANDING SEJENIS | P11: =IFERROR(__xludf.DUMMYFUNCTION("""COMPUTED_VALUE"""),"TERMINASI") -> TERMINASI | Q11: =IFERROR(__xludf.DUMMYFUNCTION("""COMPUTED_VALUE"""),23.0) -> 23 | R11: =IFERROR(__xludf.DUMMYFUNCTION("""COMPUTED_VALUE"""),23.0) -> 23 | S11: =IFERROR(__xludf.DUMMYFUNCTION("""COMPUTED_VALUE"""),23.0) -> 23 | U11: =IFERROR(__xludf.DUMMYFUNCTION("""COMPUTED_VALUE"""),"BAIK") -> BAIK | V11: =IFERROR(__xludf.DUMMYFUNCTION("""COMPUTED_VALUE"""),"Tidak Ada") -> Tidak Ada | AC11: =IFERROR(__xludf.DUMMYFUNCTION("""COMPUTED_VALUE"""),"INSPEKSI SUTM - T2_Images/5382c293.FOTO.071629.jpg") -> INSPEKSI SUTM - T2_Images/5382c293.FOTO.071629.jpg | AF11: =IFERROR(__xludf.DUMMYFUNCTION("""COMPUTED_VALUE"""),"BELUM") -> BELUM | AG11: =IFERROR(__xludf.DUMMYFUNCTION("""COMPUTED_VALUE"""),46030.0) -> 46030
A12: =IFERROR(__xludf.DUMMYFUNCTION("""COMPUTED_VALUE"""),"e9745e21") -> e9745e21 | B12: =IFERROR(__xludf.DUMMYFUNCTION("""COMPUTED_VALUE"""),46030.844814814816) -> 46030.845 | C12: =IFERROR(__xludf.DUMMYFUNCTION("""COMPUTED_VALUE"""),"-6.899156, 107.641230") -> -6.899156, 107.641230 | D12: =IFERROR(__xludf.DUMMYFUNCTION("""COMPUTED_VALUE"""),"Sandi angga") -> Sandi angga | E12: =IFERROR(__xludf.DUMMYFUNCTION("""COMPUTED_VALUE"""),"BANDUNG") -> BANDUNG | F12: =IFERROR(__xludf.DUMMYFUNCTION("""COMPUTED_VALUE"""),"BANDUNG TIMUR") -> BANDUNG TIMUR | G12: =IFERROR(__xludf.DUMMYFUNCTION("""COMPUTED_VALUE"""),"KIARACONDONG") -> KIARACONDONG | H12: =IFERROR(__xludf.DUMMYFUNCTION("""COMPUTED_VALUE"""),"KPO") -> KPO | I12: =IFERROR(__xludf.DUMMYFUNCTION("""COMPUTED_VALUE"""),"LBS BKNA-RAT") -> LBS BKNA-RAT | J12: =IFERROR(__xludf.DUMMYFUNCTION("""COMPUTED_VALUE"""),"ZONA 2") -> ZONA 2 | K12: =IFERROR(__xludf.DUMMYFUNCTION("""COMPUTED_VALUE"""),"031") -> 031 | L12: =IFERROR(__xludf.DUMMYFUNCTION("""COMPUTED_VALUE"""),"TM - 4B/H (Afspan)") -> TM - 4B/H (Afspan) | M12: =IFERROR(__xludf.DUMMYFUNCTION("""COMPUTED_VALUE"""),"Tidak Ada") -> Tidak Ada | O12: =IFERROR(__xludf.DUMMYFUNCTION("""COMPUTED_VALUE"""),"PEMBANDING SEJENIS") -> PEMBANDING SEJENIS | P12: =IFERROR(__xludf.DUMMYFUNCTION("""COMPUTED_VALUE"""),"KONEKTOR/JUMPER") -> KONEKTOR/JUMPER | Q12: =IFERROR(__xludf.DUMMYFUNCTION("""COMPUTED_VALUE"""),25.0) -> 25 | R12: =IFERROR(__xludf.DUMMYFUNCTION("""COMPUTED_VALUE"""),25.0) -> 25 | S12: =IFERROR(__xludf.DUMMYFUNCTION("""COMPUTED_VALUE"""),25.0) -> 25 | U12: =IFERROR(__xludf.DUMMYFUNCTION("""COMPUTED_VALUE"""),"BAIK") -> BAIK | V12: =IFERROR(__xludf.DUMMYFUNCTION("""COMPUTED_VALUE"""),"Tidak Ada") -> Tidak Ada | AC12: =IFERROR(__xludf.DUMMYFUNCTION("""COMPUTED_VALUE"""),"INSPEKSI SUTM - T2_Images/e9745e21.FOTO.072142.jpg") -> INSPEKSI SUTM - T2_Images/e9745e21.FOTO.072142.jpg | AF12: =IFERROR(__xludf.DUMMYFUNCTION("""COMPUTED_VALUE"""),"BELUM") -> BELUM | AG12: =IFERROR(__xludf.DUMMYFUNCTION("""COMPUTED_VALUE"""),46030.0) -> 46030
A13: =IFERROR(__xludf.DUMMYFUNCTION("""COMPUTED_VALUE"""),"01375cec") -> 01375cec | B13: =IFERROR(__xludf.DUMMYFUNCTION("""COMPUTED_VALUE"""),46030.847974537035) -> 46030.848 | C13: =IFERROR(__xludf.DUMMYFUNCTION("""COMPUTED_VALUE"""),"-6.899160, 107.641251") -> -6.899160, 107.641251 | D13: =IFERROR(__xludf.DUMMYFUNCTION("""COMPUTED_VALUE"""),"Sandi angga") -> Sandi angga | E13: =IFERROR(__xludf.DUMMYFUNCTION("""COMPUTED_VALUE"""),"BANDUNG") -> BANDUNG | F13: =IFERROR(__xludf.DUMMYFUNCTION("""COMPUTED_VALUE"""),"BANDUNG TIMUR") -> BANDUNG TIMUR | G13: =IFERROR(__xludf.DUMMYFUNCTION("""COMPUTED_VALUE"""),"KIARACONDONG") -> KIARACONDONG | H13: =IFERROR(__xludf.DUMMYFUNCTION("""COMPUTED_VALUE"""),"KPO") -> KPO | I13: =IFERROR(__xludf.DUMMYFUNCTION("""COMPUTED_VALUE"""),"LBS BKNA-RAT") -> LBS BKNA-RAT | J13: =IFERROR(__xludf.DUMMYFUNCTION("""COMPUTED_VALUE"""),"ZONA 2") -> ZONA 2 | K13: =IFERROR(__xludf.DUMMYFUNCTION("""COMPUTED_VALUE"""),"036") -> 036 | L13: =IFERROR(__xludf.DUMMYFUNCTION("""COMPUTED_VALUE"""),"TM - 4B/H (Afspan)") -> TM - 4B/H (Afspan) | M13: =IFERROR(__xludf.DUMMYFUNCTION("""COMPUTED_VALUE"""),"Tidak Ada") -> Tidak Ada | O13: =IFERROR(__xludf.DUMMYFUNCTION("""COMPUTED_VALUE"""),"PEMBANDING SEJENIS") -> PEMBANDING SEJENIS | P13: =IFERROR(__xludf.DUMMYFUNCTION("""COMPUTED_VALUE"""),"KONEKTOR/JUMPER") -> KONEKTOR/JUMPER | Q13: =IFERROR(__xludf.DUMMYFUNCTION("""COMPUTED_VALUE"""),24.0) -> 24 | R13: =IFERROR(__xludf.DUMMYFUNCTION("""COMPUTED_VALUE"""),23.0) -> 23 | S13: =IFERROR(__xludf.DUMMYFUNCTION("""COMPUTED_VALUE"""),24.0) -> 24 | U13: =IFERROR(__xludf.DUMMYFUNCTION("""COMPUTED_VALUE"""),"BAIK") -> BAIK | V13: =IFERROR(__xludf.DUMMYFUNCTION("""COMPUTED_VALUE"""),"Tidak Ada") -> Tidak Ada | AC13: =IFERROR(__xludf.DUMMYFUNCTION("""COMPUTED_VALUE"""),"INSPEKSI SUTM - T2_Images/01375cec.FOTO.072330.jpg") -> INSPEKSI SUTM - T2_Images/01375cec.FOTO.072330.jpg | AF13: =IFERROR(__xludf.DUMMYFUNCTION("""COMPUTED_VALUE"""),"BELUM") -> BELUM | AG13: =IFERROR(__xludf.DUMMYFUNCTION("""COMPUTED_VALUE"""),46030.0) -> 46030
A14: =IFERROR(__xludf.DUMMYFUNCTION("""COMPUTED_VALUE"""),"7e44f421") -> 7e44f421 | B14: =IFERROR(__xludf.DUMMYFUNCTION("""COMPUTED_VALUE"""),46031.807071759256) -> 46031.807 | C14: =IFERROR(__xludf.DUMMYFUNCTION("""COMPUTED_VALUE"""),"-6.899169, 107.641248") -> -6.899169, 107.641248 | D14: =IFERROR(__xludf.DUMMYFUNCTION("""COMPUTED_VALUE"""),"Ssndi angga") -> Ssndi angga | E14: =IFERROR(__xludf.DUMMYFUNCTION("""COMPUTED_VALUE"""),"BANDUNG") -> BANDUNG | F14: =IFERROR(__xludf.DUMMYFUNCTION("""COMPUTED_VALUE"""),"BANDUNG TIMUR") -> BANDUNG TIMUR | G14: =IFERROR(__xludf.DUMMYFUNCTION("""COMPUTED_VALUE"""),"KIARACONDONG") -> KIARACONDONG | H14: =IFERROR(__xludf.DUMMYFUNCTION("""COMPUTED_VALUE"""),"KPO") -> KPO | I14: =IFERROR(__xludf.DUMMYFUNCTION("""COMPUTED_VALUE"""),"LBS BKNA-RAT") -> LBS BKNA-RAT | J14: =IFERROR(__xludf.DUMMYFUNCTION("""COMPUTED_VALUE"""),"ZONA 2") -> ZONA 2 | K14: =IFERROR(__xludf.DUMMYFUNCTION("""COMPUTED_VALUE"""),"041") -> 041 | L14: =IFERROR(__xludf.DUMMYFUNCTION("""COMPUTED_VALUE"""),"TM - 8B/H (Percabangan)") -> TM - 8B/H (Percabangan) | M14: =IFERROR(__xludf.DUMMYFUNCTION("""COMPUTED_VALUE"""),"Tidak Ada") -> Tidak Ada | O14: =IFERROR(__xludf.DUMMYFUNCTION("""COMPUTED_VALUE"""),"PEMBANDING SEJENIS") -> PEMBANDING SEJENIS | P14: =IFERROR(__xludf.DUMMYFUNCTION("""COMPUTED_VALUE"""),"KONEKTOR/JUMPER") -> KONEKTOR/JUMPER | Q14: =IFERROR(__xludf.DUMMYFUNCTION("""COMPUTED_VALUE"""),23.0) -> 23 | R14: =IFERROR(__xludf.DUMMYFUNCTION("""COMPUTED_VALUE"""),23.0) -> 23 | S14: =IFERROR(__xludf.DUMMYFUNCTION("""COMPUTED_VALUE"""),22.0) -> 22 | U14: =IFERROR(__xludf.DUMMYFUNCTION("""COMPUTED_VALUE"""),"BAIK") -> BAIK | V14: =IFERROR(__xludf.DUMMYFUNCTION("""COMPUTED_VALUE"""),"Tidak Ada") -> Tidak Ada | AC14: =IFERROR(__xludf.DUMMYFUNCTION("""COMPUTED_VALUE"""),"INSPEKSI SUTM - T2_Images/7e44f421.FOTO.072712.jpg") -> INSPEKSI SUTM - T2_Images/7e44f421.FOTO.072712.jpg | AF14: =IFERROR(__xludf.DUMMYFUNCTION("""COMPUTED_VALUE"""),"BELUM") -> BELUM | AG14: =IFERROR(__xludf.DUMMYFUNCTION("""COMPUTED_VALUE"""),46031.0) -> 46031
A15: =IFERROR(__xludf.DUMMYFUNCTION("""COMPUTED_VALUE"""),"409cc280") -> 409cc280 | B15: =IFERROR(__xludf.DUMMYFUNCTION("""COMPUTED_VALUE"""),46031.809375) -> 46031.809 | C15: =IFERROR(__xludf.DUMMYFUNCTION("""COMPUTED_VALUE"""),"-6.899189, 107.641263") -> -6.899189, 107.641263 | D15: =IFERROR(__xludf.DUMMYFUNCTION("""COMPUTED_VALUE"""),"Sandi angga") -> Sandi angga | E15: =IFERROR(__xludf.DUMMYFUNCTION("""COMPUTED_VALUE"""),"BANDUNG") -> BANDUNG | F15: =IFERROR(__xludf.DUMMYFUNCTION("""COMPUTED_VALUE"""),"BANDUNG TIMUR") -> BANDUNG TIMUR | G15: =IFERROR(__xludf.DUMMYFUNCTION("""COMPUTED_VALUE"""),"KIARACONDONG") -> KIARACONDONG | H15: =IFERROR(__xludf.DUMMYFUNCTION("""COMPUTED_VALUE"""),"KPO") -> KPO | I15: =IFERROR(__xludf.DUMMYFUNCTION("""COMPUTED_VALUE"""),"LBS BKNA-RAT") -> LBS BKNA-RAT | J15: =IFERROR(__xludf.DUMMYFUNCTION("""COMPUTED_VALUE"""),"ZONA 2") -> ZONA 2 | K15: =IFERROR(__xludf.DUMMYFUNCTION("""COMPUTED_VALUE"""),"041L07") -> 041L07 | L15: =IFERROR(__xludf.DUMMYFUNCTION("""COMPUTED_VALUE"""),"TM - 8B/H (Percabangan)") -> TM - 8B/H (Percabangan) | M15: =IFERROR(__xludf.DUMMYFUNCTION("""COMPUTED_VALUE"""),"Gardu") -> Gardu | N15: =IFERROR(__xludf.DUMMYFUNCTION("""COMPUTED_VALUE"""),"BRC") -> BRC | O15: =IFERROR(__xludf.DUMMYFUNCTION("""COMPUTED_VALUE"""),"PEMBANDING SEJENIS") -> PEMBANDING SEJENIS | P15: =IFERROR(__xludf.DUMMYFUNCTION("""COMPUTED_VALUE"""),"KONEKTOR/JUMPER") -> KONEKTOR/JUMPER | Q15: =IFERROR(__xludf.DUMMYFUNCTION("""COMPUTED_VALUE"""),25.0) -> 25 | R15: =IFERROR(__xludf.DUMMYFUNCTION("""COMPUTED_VALUE"""),24.0) -> 24 | S15: =IFERROR(__xludf.DUMMYFUNCTION("""COMPUTED_VALUE"""),24.0) -> 24 | U15: =IFERROR(__xludf.DUMMYFUNCTION("""COMPUTED_VALUE"""),"BAIK") -> BAIK | V15: =IFERROR(__xludf.DUMMYFUNCTION("""COMPUTED_VALUE"""),"Tidak Ada") -> Tidak Ada | AC15: =IFERROR(__xludf.DUMMYFUNCTION("""COMPUTED_VALUE"""),"INSPEKSI SUTM - T2_Images/409cc280.FOTO.072930.jpg") -> INSPEKSI SUTM - T2_Images/409cc280.FOTO.072930.jpg | AF15: =IFERROR(__xludf.DUMMYFUNCTION("""COMPUTED_VALUE"""),"BELUM") -> BELUM | AG15: =IFERROR(__xludf.DUMMYFUNCTION("""COMPUTED_VALUE"""),46031.0) -> 46031
A16: =IFERROR(__xludf.DUMMYFUNCTION("""COMPUTED_VALUE"""),"dfa78c97") -> dfa78c97 | B16: =IFERROR(__xludf.DUMMYFUNCTION("""COMPUTED_VALUE"""),46031.81269675926) -> 46031.813 | C16: =IFERROR(__xludf.DUMMYFUNCTION("""COMPUTED_VALUE"""),"-6.899202, 107.641241") -> -6.899202, 107.641241 | D16: =IFERROR(__xludf.DUMMYFUNCTION("""COMPUTED_VALUE"""),"Sandi angga") -> Sandi angga | E16: =IFERROR(__xludf.DUMMYFUNCTION("""COMPUTED_VALUE"""),"BANDUNG") -> BANDUNG | F16: =IFERROR(__xludf.DUMMYFUNCTION("""COMPUTED_VALUE"""),"BANDUNG TIMUR") -> BANDUNG TIMUR | G16: =IFERROR(__xludf.DUMMYFUNCTION("""COMPUTED_VALUE"""),"KIARACONDONG") -> KIARACONDONG | H16: =IFERROR(__xludf.DUMMYFUNCTION("""COMPUTED_VALUE"""),"KPO") -> KPO | I16: =IFERROR(__xludf.DUMMYFUNCTION("""COMPUTED_VALUE"""),"LBS BKNA-RAT") -> LBS BKNA-RAT | J16: =IFERROR(__xludf.DUMMYFUNCTION("""COMPUTED_VALUE"""),"ZONA 2") -> ZONA 2 | K16: =IFERROR(__xludf.DUMMYFUNCTION("""COMPUTED_VALUE"""),"041L07R01") -> 041L07R01 | L16: =IFERROR(__xludf.DUMMYFUNCTION("""COMPUTED_VALUE"""),"TM - 4B/H (Afspan)") -> TM - 4B/H (Afspan) | M16: =IFERROR(__xludf.DUMMYFUNCTION("""COMPUTED_VALUE"""),"Tidak Ada") -> Tidak Ada | O16: =IFERROR(__xludf.DUMMYFUNCTION("""COMPUTED_VALUE"""),"PEMBANDING SEJENIS") -> PEMBANDING SEJENIS | P16: =IFERROR(__xludf.DUMMYFUNCTION("""COMPUTED_VALUE"""),"KONEKTOR/JUMPER") -> KONEKTOR/JUMPER | Q16: =IFERROR(__xludf.DUMMYFUNCTION("""COMPUTED_VALUE"""),24.0) -> 24 | R16: =IFERROR(__xludf.DUMMYFUNCTION("""COMPUTED_VALUE"""),24.0) -> 24 | S16: =IFERROR(__xludf.DUMMYFUNCTION("""COMPUTED_VALUE"""),24.0) -> 24 | U16: =IFERROR(__xludf.DUMMYFUNCTION("""COMPUTED_VALUE"""),"BAIK") -> BAIK | V16: =IFERROR(__xludf.DUMMYFUNCTION("""COMPUTED_VALUE"""),"Tidak Ada") -> Tidak Ada | AC16: =IFERROR(__xludf.DUMMYFUNCTION("""COMPUTED_VALUE"""),"INSPEKSI SUTM - T2_Images/dfa78c97.FOTO.073828.jpg") -> INSPEKSI SUTM - T2_Images/dfa78c97.FOTO.073828.jpg | AF16: =IFERROR(__xludf.DUMMYFUNCTION("""COMPUTED_VALUE"""),"BELUM") -> BELUM | AG16: =IFERROR(__xludf.DUMMYFUNCTION("""COMPUTED_VALUE"""),46031.0) -> 46031
A17: =IFERROR(__xludf.DUMMYFUNCTION("""COMPUTED_VALUE"""),"9f7a1c38") -> 9f7a1c38 | B17: =IFERROR(__xludf.DUMMYFUNCTION("""COMPUTED_VALUE"""),46031.81439814815) -> 46031.814 | C17: =IFERROR(__xludf.DUMMYFUNCTION("""COMPUTED_VALUE"""),"-6.952244, 107.800936") -> -6.952244, 107.800936 | D17: =IFERROR(__xludf.DUMMYFUNCTION("""COMPUTED_VALUE"""),"Sandi angga") -> Sandi angga | E17: =IFERROR(__xludf.DUMMYFUNCTION("""COMPUTED_VALUE"""),"BANDUNG") -> BANDUNG | F17: =IFERROR(__xludf.DUMMYFUNCTION("""COMPUTED_VALUE"""),"BANDUNG TIMUR") -> BANDUNG TIMUR | G17: =IFERROR(__xludf.DUMMYFUNCTION("""COMPUTED_VALUE"""),"KIARACONDONG") -> KIARACONDONG | H17: =IFERROR(__xludf.DUMMYFUNCTION("""COMPUTED_VALUE"""),"KPO") -> KPO | I17: =IFERROR(__xludf.DUMMYFUNCTION("""COMPUTED_VALUE"""),"LBS BKNA-RAT") -> LBS BKNA-RAT | J17: =IFERROR(__xludf.DUMMYFUNCTION("""COMPUTED_VALUE"""),"ZONA 2") -> ZONA 2 | K17: =IFERROR(__xludf.DUMMYFUNCTION("""COMPUTED_VALUE"""),"041L08") -> 041L08 | L17: =IFERROR(__xludf.DUMMYFUNCTION("""COMPUTED_VALUE"""),"TM - 8B/H (Percabangan)") -> TM - 8B/H (Percabangan) | M17: =IFERROR(__xludf.DUMMYFUNCTION("""COMPUTED_VALUE"""),"Tidak Ada") -> Tidak Ada | O17: =IFERROR(__xludf.DUMMYFUNCTION("""COMPUTED_VALUE"""),"PEMBANDING SEJENIS") -> PEMBANDING SEJENIS | P17: =IFERROR(__xludf.DUMMYFUNCTION("""COMPUTED_VALUE"""),"KONEKTOR/JUMPER") -> KONEKTOR/JUMPER | Q17: =IFERROR(__xludf.DUMMYFUNCTION("""COMPUTED_VALUE"""),24.0) -> 24 | R17: =IFERROR(__xludf.DUMMYFUNCTION("""COMPUTED_VALUE"""),25.0) -> 25 | S17: =IFERROR(__xludf.DUMMYFUNCTION("""COMPUTED_VALUE"""),24.0) -> 24 | U17: =IFERROR(__xludf.DUMMYFUNCTION("""COMPUTED_VALUE"""),"BAIK") -> BAIK | V17: =IFERROR(__xludf.DUMMYFUNCTION("""COMPUTED_VALUE"""),"Tidak Ada") -> Tidak Ada | AC17: =IFERROR(__xludf.DUMMYFUNCTION("""COMPUTED_VALUE"""),"INSPEKSI SUTM - T2_Images/9f7a1c38.FOTO.073839.jpg") -> INSPEKSI SUTM - T2_Images/9f7a1c38.FOTO.073839.jpg | AF17: =IFERROR(__xludf.DUMMYFUNCTION("""COMPUTED_VALUE"""),"BELUM") -> BELUM | AG17: =IFERROR(__xludf.DUMMYFUNCTION("""COMPUTED_VALUE"""),46031.0) -> 46031
A18: =IFERROR(__xludf.DUMMYFUNCTION("""COMPUTED_VALUE"""),"c343748b") -> c343748b | B18: =IFERROR(__xludf.DUMMYFUNCTION("""COMPUTED_VALUE"""),46031.81560185185) -> 46031.816 | C18: =IFERROR(__xludf.DUMMYFUNCTION("""COMPUTED_VALUE"""),"-6.899184, 107.641239") -> -6.899184, 107.641239 | D18: =IFERROR(__xludf.DUMMYFUNCTION("""COMPUTED_VALUE"""),"Sandi angga") -> Sandi angga | E18: =IFERROR(__xludf.DUMMYFUNCTION("""COMPUTED_VALUE"""),"BANDUNG") -> BANDUNG | F18: =IFERROR(__xludf.DUMMYFUNCTION("""COMPUTED_VALUE"""),"BANDUNG TIMUR") -> BANDUNG TIMUR | G18: =IFERROR(__xludf.DUMMYFUNCTION("""COMPUTED_VALUE"""),"KIARACONDONG") -> KIARACONDONG | H18: =IFERROR(__xludf.DUMMYFUNCTION("""COMPUTED_VALUE"""),"KPO") -> KPO | I18: =IFERROR(__xludf.DUMMYFUNCTION("""COMPUTED_VALUE"""),"LBS BKNA-RAT") -> LBS BKNA-RAT | J18: =IFERROR(__xludf.DUMMYFUNCTION("""COMPUTED_VALUE"""),"ZONA 2") -> ZONA 2 | K18: =IFERROR(__xludf.DUMMYFUNCTION("""COMPUTED_VALUE"""),"041L08L03") -> 041L08L03 | L18: =IFERROR(__xludf.DUMMYFUNCTION("""COMPUTED_VALUE"""),"TM - 7B/H (Afspan 90 Derajat)") -> TM - 7B/H (Afspan 90 Derajat) | M18: =IFERROR(__xludf.DUMMYFUNCTION("""COMPUTED_VALUE"""),"Tidak Ada") -> Tidak Ada | O18: =IFERROR(__xludf.DUMMYFUNCTION("""COMPUTED_VALUE"""),"PEMBANDING SEJENIS") -> PEMBANDING SEJENIS | P18: =IFERROR(__xludf.DUMMYFUNCTION("""COMPUTED_VALUE"""),"KONEKTOR/JUMPER") -> KONEKTOR/JUMPER | Q18: =IFERROR(__xludf.DUMMYFUNCTION("""COMPUTED_VALUE"""),25.0) -> 25 | R18: =IFERROR(__xludf.DUMMYFUNCTION("""COMPUTED_VALUE"""),25.0) -> 25 | S18: =IFERROR(__xludf.DUMMYFUNCTION("""COMPUTED_VALUE"""),24.0) -> 24 | U18: =IFERROR(__xludf.DUMMYFUNCTION("""COMPUTED_VALUE"""),"BAIK") -> BAIK | V18: =IFERROR(__xludf.DUMMYFUNCTION("""COMPUTED_VALUE"""),"Tidak Ada") -> Tidak Ada | AC18: =IFERROR(__xludf.DUMMYFUNCTION("""COMPUTED_VALUE"""),"INSPEKSI SUTM - T2_Images/c343748b.FOTO.073847.jpg") -> INSPEKSI SUTM - T2_Images/c343748b.FOTO.073847.jpg | AF18: =IFERROR(__xludf.DUMMYFUNCTION("""COMPUTED_VALUE"""),"BELUM") -> BELUM | AG18: =IFERROR(__xludf.DUMMYFUNCTION("""COMPUTED_VALUE"""),46031.0) -> 46031
A19: =IFERROR(__xludf.DUMMYFUNCTION("""COMPUTED_VALUE"""),"f3fd9701") -> f3fd9701 | B19: =IFERROR(__xludf.DUMMYFUNCTION("""COMPUTED_VALUE"""),46031.81630787037) -> 46031.816 | C19: =IFERROR(__xludf.DUMMYFUNCTION("""COMPUTED_VALUE"""),"-6.899161, 107.641241") -> -6.899161, 107.641241 | D19: =IFERROR(__xludf.DUMMYFUNCTION("""COMPUTED_VALUE"""),"Sandi angga") -> Sandi angga | E19: =IFERROR(__xludf.DUMMYFUNCTION("""COMPUTED_VALUE"""),"BANDUNG") -> BANDUNG | F19: =IFERROR(__xludf.DUMMYFUNCTION("""COMPUTED_VALUE"""),"BANDUNG TIMUR") -> BANDUNG TIMUR | G19: =IFERROR(__xludf.DUMMYFUNCTION("""COMPUTED_VALUE"""),"KIARACONDONG") -> KIARACONDONG | H19: =IFERROR(__xludf.DUMMYFUNCTION("""COMPUTED_VALUE"""),"KPO") -> KPO | I19: =IFERROR(__xludf.DUMMYFUNCTION("""COMPUTED_VALUE"""),"LBS BKNA-RAT") -> LBS BKNA-RAT | J19: =IFERROR(__xludf.DUMMYFUNCTION("""COMPUTED_VALUE"""),"ZONA 2") -> ZONA 2 | K19: =IFERROR(__xludf.DUMMYFUNCTION("""COMPUTED_VALUE"""),"041L08L04") -> 041L08L04 | L19: =IFERROR(__xludf.DUMMYFUNCTION("""COMPUTED_VALUE"""),"TM - 7B/H (Afspan 90 Derajat)") -> TM - 7B/H (Afspan 90 Derajat) | M19: =IFERROR(__xludf.DUMMYFUNCTION("""COMPUTED_VALUE"""),"Tidak Ada") -> Tidak Ada | O19: =IFERROR(__xludf.DUMMYFUNCTION("""COMPUTED_VALUE"""),"PEMBANDING SEJENIS") -> PEMBANDING SEJENIS | P19: =IFERROR(__xludf.DUMMYFUNCTION("""COMPUTED_VALUE"""),"KONEKTOR/JUMPER") -> KONEKTOR/JUMPER | Q19: =IFERROR(__xludf.DUMMYFUNCTION("""COMPUTED_VALUE"""),24.0) -> 24 | R19: =IFERROR(__xludf.DUMMYFUNCTION("""COMPUTED_VALUE"""),25.0) -> 25 | S19: =IFERROR(__xludf.DUMMYFUNCTION("""COMPUTED_VALUE"""),26.0) -> 26 | U19: =IFERROR(__xludf.DUMMYFUNCTION("""COMPUTED_VALUE"""),"BAIK") -> BAIK | V19: =IFERROR(__xludf.DUMMYFUNCTION("""COMPUTED_VALUE"""),"Tidak Ada") -> Tidak Ada | AC19: =IFERROR(__xludf.DUMMYFUNCTION("""COMPUTED_VALUE"""),"INSPEKSI SUTM - T2_Images/f3fd9701.FOTO.073856.jpg") -> INSPEKSI SUTM - T2_Images/f3fd9701.FOTO.073856.jpg | AF19: =IFERROR(__xludf.DUMMYFUNCTION("""COMPUTED_VALUE"""),"BELUM") -> BELUM | AG19: =IFERROR(__xludf.DUMMYFUNCTION("""COMPUTED_VALUE"""),46031.0) -> 46031
A20: =IFERROR(__xludf.DUMMYFUNCTION("""COMPUTED_VALUE"""),"1c8bdfd9") -> 1c8bdfd9 | B20: =IFERROR(__xludf.DUMMYFUNCTION("""COMPUTED_VALUE"""),46031.81693287037) -> 46031.817 | C20: =IFERROR(__xludf.DUMMYFUNCTION("""COMPUTED_VALUE"""),"-6.899162, 107.641241") -> -6.899162, 107.641241 | D20: =IFERROR(__xludf.DUMMYFUNCTION("""COMPUTED_VALUE"""),"Sandi angga") -> Sandi angga | E20: =IFERROR(__xludf.DUMMYFUNCTION("""COMPUTED_VALUE"""),"BANDUNG") -> BANDUNG | F20: =IFERROR(__xludf.DUMMYFUNCTION("""COMPUTED_VALUE"""),"BANDUNG TIMUR") -> BANDUNG TIMUR | G20: =IFERROR(__xludf.DUMMYFUNCTION("""COMPUTED_VALUE"""),"KIARACONDONG") -> KIARACONDONG | H20: =IFERROR(__xludf.DUMMYFUNCTION("""COMPUTED_VALUE"""),"KPO") -> KPO | I20: =IFERROR(__xludf.DUMMYFUNCTION("""COMPUTED_VALUE"""),"LBS BKNA-RAT") -> LBS BKNA-RAT | J20: =IFERROR(__xludf.DUMMYFUNCTION("""COMPUTED_VALUE"""),"ZONA 2") -> ZONA 2 | K20: =IFERROR(__xludf.DUMMYFUNCTION("""COMPUTED_VALUE"""),"041L08L07") -> 041L08L07 | L20: =IFERROR(__xludf.DUMMYFUNCTION("""COMPUTED_VALUE"""),"TM - 1B/H (Tumpu)") -> TM - 1B/H (Tumpu) | M20: =IFERROR(__xludf.DUMMYFUNCTION("""COMPUTED_VALUE"""),"Tidak Ada") -> Tidak Ada | O20: =IFERROR(__xludf.DUMMYFUNCTION("""COMPUTED_VALUE"""),"PEMBANDING SEJENIS") -> PEMBANDING SEJENIS | P20: =IFERROR(__xludf.DUMMYFUNCTION("""COMPUTED_VALUE"""),"ARRESTER") -> ARRESTER | Q20: =IFERROR(__xludf.DUMMYFUNCTION("""COMPUTED_VALUE"""),24.0) -> 24 | R20: =IFERROR(__xludf.DUMMYFUNCTION("""COMPUTED_VALUE"""),24.0) -> 24 | S20: =IFERROR(__xludf.DUMMYFUNCTION("""COMPUTED_VALUE"""),24.0) -> 24 | U20: =IFERROR(__xludf.DUMMYFUNCTION("""COMPUTED_VALUE"""),"BAIK") -> BAIK | V20: =IFERROR(__xludf.DUMMYFUNCTION("""COMPUTED_VALUE"""),"Tidak Ada") -> Tidak Ada | AC20: =IFERROR(__xludf.DUMMYFUNCTION("""COMPUTED_VALUE"""),"INSPEKSI SUTM - T2_Images/1c8bdfd9.FOTO.073909.jpg") -> INSPEKSI SUTM - T2_Images/1c8bdfd9.FOTO.073909.jpg | AF20: =IFERROR(__xludf.DUMMYFUNCTION("""COMPUTED_VALUE"""),"BELUM") -> BELUM | AG20: =IFERROR(__xludf.DUMMYFUNCTION("""COMPUTED_VALUE"""),46031.0) -> 46031
A21: =IFERROR(__xludf.DUMMYFUNCTION("""COMPUTED_VALUE"""),"a6aa7890") -> a6aa7890 | B21: =IFERROR(__xludf.DUMMYFUNCTION("""COMPUTED_VALUE"""),46031.81769675926) -> 46031.818 | C21: =IFERROR(__xludf.DUMMYFUNCTION("""COMPUTED_VALUE"""),"-6.899161, 107.641239") -> -6.899161, 107.641239 | D21: =IFERROR(__xludf.DUMMYFUNCTION("""COMPUTED_VALUE"""),"Sandi angga") -> Sandi angga | E21: =IFERROR(__xludf.DUMMYFUNCTION("""COMPUTED_VALUE"""),"BANDUNG") -> BANDUNG | F21: =IFERROR(__xludf.DUMMYFUNCTION("""COMPUTED_VALUE"""),"BANDUNG TIMUR") -> BANDUNG TIMUR | G21: =IFERROR(__xludf.DUMMYFUNCTION("""COMPUTED_VALUE"""),"KIARACONDONG") -> KIARACONDONG | H21: =IFERROR(__xludf.DUMMYFUNCTION("""COMPUTED_VALUE"""),"KPO") -> KPO | I21: =IFERROR(__xludf.DUMMYFUNCTION("""COMPUTED_VALUE"""),"LBS BKNA-RAT") -> LBS BKNA-RAT | J21: =IFERROR(__xludf.DUMMYFUNCTION("""COMPUTED_VALUE"""),"ZONA 2") -> ZONA 2 | K21: =IFERROR(__xludf.DUMMYFUNCTION("""COMPUTED_VALUE"""),"041L08L011") -> 041L08L011 | L21: =IFERROR(__xludf.DUMMYFUNCTION("""COMPUTED_VALUE"""),"TM - 1B/H (Tumpu)") -> TM - 1B/H (Tumpu) | M21: =IFERROR(__xludf.DUMMYFUNCTION("""COMPUTED_VALUE"""),"Tidak Ada") -> Tidak Ada | O21: =IFERROR(__xludf.DUMMYFUNCTION("""COMPUTED_VALUE"""),"PEMBANDING SEJENIS") -> PEMBANDING SEJENIS | P21: =IFERROR(__xludf.DUMMYFUNCTION("""COMPUTED_VALUE"""),"ARRESTER") -> ARRESTER | Q21: =IFERROR(__xludf.DUMMYFUNCTION("""COMPUTED_VALUE"""),25.0) -> 25 | R21: =IFERROR(__xludf.DUMMYFUNCTION("""COMPUTED_VALUE"""),25.0) -> 25 | S21: =IFERROR(__xludf.DUMMYFUNCTION("""COMPUTED_VALUE"""),25.0) -> 25 | U21: =IFERROR(__xludf.DUMMYFUNCTION("""COMPUTED_VALUE"""),"BAIK") -> BAIK | V21: =IFERROR(__xludf.DUMMYFUNCTION("""COMPUTED_VALUE"""),"Tidak Ada") -> Tidak Ada | AC21: =IFERROR(__xludf.DUMMYFUNCTION("""COMPUTED_VALUE"""),"INSPEKSI SUTM - T2_Images/a6aa7890.FOTO.074032.jpg") -> INSPEKSI SUTM - T2_Images/a6aa7890.FOTO.074032.jpg | AF21: =IFERROR(__xludf.DUMMYFUNCTION("""COMPUTED_VALUE"""),"BELUM") -> BELUM | AG21: =IFERROR(__xludf.DUMMYFUNCTION("""COMPUTED_VALUE"""),46031.0) -> 46031
A22: =IFERROR(__xludf.DUMMYFUNCTION("""COMPUTED_VALUE"""),"040855b4") -> 040855b4 | B22: =IFERROR(__xludf.DUMMYFUNCTION("""COMPUTED_VALUE"""),46031.81859953704) -> 46031.819 | C22: =IFERROR(__xludf.DUMMYFUNCTION("""COMPUTED_VALUE"""),"-6.899148, 107.641140") -> -6.899148, 107.641140 | D22: =IFERROR(__xludf.DUMMYFUNCTION("""COMPUTED_VALUE"""),"Sandi angga") -> Sandi angga | E22: =IFERROR(__xludf.DUMMYFUNCTION("""COMPUTED_VALUE"""),"BANDUNG") -> BANDUNG | F22: =IFERROR(__xludf.DUMMYFUNCTION("""COMPUTED_VALUE"""),"BANDUNG TIMUR") -> BANDUNG TIMUR | G22: =IFERROR(__xludf.DUMMYFUNCTION("""COMPUTED_VALUE"""),"KIARACONDONG") -> KIARACONDONG | H22: =IFERROR(__xludf.DUMMYFUNCTION("""COMPUTED_VALUE"""),"KPO") -> KPO | I22: =IFERROR(__xludf.DUMMYFUNCTION("""COMPUTED_VALUE"""),"LBS BKNA-RAT") -> LBS BKNA-RAT | J22: =IFERROR(__xludf.DUMMYFUNCTION("""COMPUTED_VALUE"""),"ZONA 2") -> ZONA 2 | K22: =IFERROR(__xludf.DUMMYFUNCTION("""COMPUTED_VALUE"""),"041L08L012") -> 041L08L012 | L22: =IFERROR(__xludf.DUMMYFUNCTION("""COMPUTED_VALUE"""),"TM - 8B/H (Percabangan)") -> TM - 8B/H (Percabangan) | M22: =IFERROR(__xludf.DUMMYFUNCTION("""COMPUTED_VALUE"""),"Tidak Ada") -> Tidak Ada | O22: =IFERROR(__xludf.DUMMYFUNCTION("""COMPUTED_VALUE"""),"PEMBANDING SEJENIS") -> PEMBANDING SEJENIS | P22: =IFERROR(__xludf.DUMMYFUNCTION("""COMPUTED_VALUE"""),"KONEKTOR/JUMPER") -> KONEKTOR/JUMPER | Q22: =IFERROR(__xludf.DUMMYFUNCTION("""COMPUTED_VALUE"""),25.0) -> 25 | R22: =IFERROR(__xludf.DUMMYFUNCTION("""COMPUTED_VALUE"""),25.0) -> 25 | S22: =IFERROR(__xludf.DUMMYFUNCTION("""COMPUTED_VALUE"""),25.0) -> 25 | U22: =IFERROR(__xludf.DUMMYFUNCTION("""COMPUTED_VALUE"""),"BAIK") -> BAIK | V22: =IFERROR(__xludf.DUMMYFUNCTION("""COMPUTED_VALUE"""),"Tidak Ada") -> Tidak Ada | AC22: =IFERROR(__xludf.DUMMYFUNCTION("""COMPUTED_VALUE"""),"INSPEKSI SUTM - T2_Images/040855b4.FOTO.074126.jpg") -> INSPEKSI SUTM - T2_Images/040855b4.FOTO.074126.jpg | AF22: =IFERROR(__xludf.DUMMYFUNCTION("""COMPUTED_VALUE"""),"BELUM") -> BELUM | AG22: =IFERROR(__xludf.DUMMYFUNCTION("""COMPUTED_VALUE"""),46031.0) -> 46031
A23: =IFERROR(__xludf.DUMMYFUNCTION("""COMPUTED_VALUE"""),"ef8b16e4") -> ef8b16e4 | B23: =IFERROR(__xludf.DUMMYFUNCTION("""COMPUTED_VALUE"""),46031.819340277776) -> 46031.819 | C23: =IFERROR(__xludf.DUMMYFUNCTION("""COMPUTED_VALUE"""),"-6.899149, 107.641130") -> -6.899149, 107.641130 | D23: =IFERROR(__xludf.DUMMYFUNCTION("""COMPUTED_VALUE"""),"Sandi angga") -> Sandi angga | E23: =IFERROR(__xludf.DUMMYFUNCTION("""COMPUTED_VALUE"""),"BANDUNG") -> BANDUNG | F23: =IFERROR(__xludf.DUMMYFUNCTION("""COMPUTED_VALUE"""),"BANDUNG TIMUR") -> BANDUNG TIMUR | G23: =IFERROR(__xludf.DUMMYFUNCTION("""COMPUTED_VALUE"""),"KIARACONDONG") -> KIARACONDONG | H23: =IFERROR(__xludf.DUMMYFUNCTION("""COMPUTED_VALUE"""),"KPO") -> KPO | I23: =IFERROR(__xludf.DUMMYFUNCTION("""COMPUTED_VALUE"""),"LBS BKNA-RAT") -> LBS BKNA-RAT | J23: =IFERROR(__xludf.DUMMYFUNCTION("""COMPUTED_VALUE"""),"ZONA 2") -> ZONA 2 | K23: =IFERROR(__xludf.DUMMYFUNCTION("""COMPUTED_VALUE"""),"041L08L012L02") -> 041L08L012L02 | L23: =IFERROR(__xludf.DUMMYFUNCTION("""COMPUTED_VALUE"""),"TM - 14B/H (Akhir)") -> TM - 14B/H (Akhir) | M23: =IFERROR(__xludf.DUMMYFUNCTION("""COMPUTED_VALUE"""),"Tidak Ada") -> Tidak Ada | O23: =IFERROR(__xludf.DUMMYFUNCTION("""COMPUTED_VALUE"""),"PEMBANDING SEJENIS") -> PEMBANDING SEJENIS | P23: =IFERROR(__xludf.DUMMYFUNCTION("""COMPUTED_VALUE"""),"TERMINASI") -> TERMINASI | Q23: =IFERROR(__xludf.DUMMYFUNCTION("""COMPUTED_VALUE"""),25.0) -> 25 | R23: =IFERROR(__xludf.DUMMYFUNCTION("""COMPUTED_VALUE"""),25.0) -> 25 | S23: =IFERROR(__xludf.DUMMYFUNCTION("""COMPUTED_VALUE"""),25.0) -> 25 | U23: =IFERROR(__xludf.DUMMYFUNCTION("""COMPUTED_VALUE"""),"BAIK") -> BAIK | V23: =IFERROR(__xludf.DUMMYFUNCTION("""COMPUTED_VALUE"""),"Tidak Ada") -> Tidak Ada | AC23: =IFERROR(__xludf.DUMMYFUNCTION("""COMPUTED_VALUE"""),"INSPEKSI SUTM - T2_Images/ef8b16e4.FOTO.074316.jpg") -> INSPEKSI SUTM - T2_Images/ef8b16e4.FOTO.074316.jpg | AF23: =IFERROR(__xludf.DUMMYFUNCTION("""COMPUTED_VALUE"""),"BELUM") -> BELUM | AG23: =IFERROR(__xludf.DUMMYFUNCTION("""COMPUTED_VALUE"""),46031.0) -> 46031
A24: =IFERROR(__xludf.DUMMYFUNCTION("""COMPUTED_VALUE"""),"5211a791") -> 5211a791 | B24: =IFERROR(__xludf.DUMMYFUNCTION("""COMPUTED_VALUE"""),46031.821238425924) -> 46031.821 | C24: =IFERROR(__xludf.DUMMYFUNCTION("""COMPUTED_VALUE"""),"-6.899167, 107.641126") -> -6.899167, 107.641126 | D24: =IFERROR(__xludf.DUMMYFUNCTION("""COMPUTED_VALUE"""),"Sandi angga") -> Sandi angga | E24: =IFERROR(__xludf.DUMMYFUNCTION("""COMPUTED_VALUE"""),"BANDUNG") -> BANDUNG | F24: =IFERROR(__xludf.DUMMYFUNCTION("""COMPUTED_VALUE"""),"BANDUNG TIMUR") -> BANDUNG TIMUR | G24: =IFERROR(__xludf.DUMMYFUNCTION("""COMPUTED_VALUE"""),"KIARACONDONG") -> KIARACONDONG | H24: =IFERROR(__xludf.DUMMYFUNCTION("""COMPUTED_VALUE"""),"KPO") -> KPO | I24: =IFERROR(__xludf.DUMMYFUNCTION("""COMPUTED_VALUE"""),"LBS BKNA-RAT") -> LBS BKNA-RAT | J24: =IFERROR(__xludf.DUMMYFUNCTION("""COMPUTED_VALUE"""),"ZONA 2") -> ZONA 2 | K24: =IFERROR(__xludf.DUMMYFUNCTION("""COMPUTED_VALUE"""),"041L08L012R06") -> 041L08L012R06 | L24: =IFERROR(__xludf.DUMMYFUNCTION("""COMPUTED_VALUE"""),"TM - 4B/H (Afspan)") -> TM - 4B/H (Afspan) | M24: =IFERROR(__xludf.DUMMYFUNCTION("""COMPUTED_VALUE"""),"Gardu") -> Gardu | N24: =IFERROR(__xludf.DUMMYFUNCTION("""COMPUTED_VALUE"""),"CLD") -> CLD | O24: =IFERROR(__xludf.DUMMYFUNCTION("""COMPUTED_VALUE"""),"PEMBANDING SEJENIS") -> PEMBANDING SEJENIS | P24: =IFERROR(__xludf.DUMMYFUNCTION("""COMPUTED_VALUE"""),"KONEKTOR/JUMPER") -> KONEKTOR/JUMPER | Q24: =IFERROR(__xludf.DUMMYFUNCTION("""COMPUTED_VALUE"""),26.0) -> 26 | R24: =IFERROR(__xludf.DUMMYFUNCTION("""COMPUTED_VALUE"""),25.0) -> 25 | S24: =IFERROR(__xludf.DUMMYFUNCTION("""COMPUTED_VALUE"""),26.0) -> 26 | U24: =IFERROR(__xludf.DUMMYFUNCTION("""COMPUTED_VALUE"""),"BAIK") -> BAIK | V24: =IFERROR(__xludf.DUMMYFUNCTION("""COMPUTED_VALUE"""),"Tidak Ada") -> Tidak Ada | AC24: =IFERROR(__xludf.DUMMYFUNCTION("""COMPUTED_VALUE"""),"INSPEKSI SUTM - T2_Images/5211a791.FOTO.074604.jpg") -> INSPEKSI SUTM - T2_Images/5211a791.FOTO.074604.jpg | AF24: =IFERROR(__xludf.DUMMYFUNCTION("""COMPUTED_VALUE"""),"BELUM") -> BELUM | AG24: =IFERROR(__xludf.DUMMYFUNCTION("""COMPUTED_VALUE"""),46031.0) -> 46031
A25: =IFERROR(__xludf.DUMMYFUNCTION("""COMPUTED_VALUE"""),"9e60e4ac") -> 9e60e4ac | B25: =IFERROR(__xludf.DUMMYFUNCTION("""COMPUTED_VALUE"""),46031.82394675926) -> 46031.824 | C25: =IFERROR(__xludf.DUMMYFUNCTION("""COMPUTED_VALUE"""),"-6.899179, 107.641120") -> -6.899179, 107.641120 | D25: =IFERROR(__xludf.DUMMYFUNCTION("""COMPUTED_VALUE"""),"Sandi angga") -> Sandi angga | E25: =IFERROR(__xludf.DUMMYFUNCTION("""COMPUTED_VALUE"""),"BANDUNG") -> BANDUNG | F25: =IFERROR(__xludf.DUMMYFUNCTION("""COMPUTED_VALUE"""),"BANDUNG TIMUR") -> BANDUNG TIMUR | G25: =IFERROR(__xludf.DUMMYFUNCTION("""COMPUTED_VALUE"""),"KIARACONDONG") -> KIARACONDONG | H25: =IFERROR(__xludf.DUMMYFUNCTION("""COMPUTED_VALUE"""),"KPO") -> KPO | I25: =IFERROR(__xludf.DUMMYFUNCTION("""COMPUTED_VALUE"""),"LBS BKNA-RAT") -> LBS BKNA-RAT | J25: =IFERROR(__xludf.DUMMYFUNCTION("""COMPUTED_VALUE"""),"ZONA 2") -> ZONA 2 | K25: =IFERROR(__xludf.DUMMYFUNCTION("""COMPUTED_VALUE"""),"041L08L012R06") -> 041L08L012R06 | L25: =IFERROR(__xludf.DUMMYFUNCTION("""COMPUTED_VALUE"""),"TM - 4B/H (Afspan)") -> TM - 4B/H (Afspan) | M25: =IFERROR(__xludf.DUMMYFUNCTION("""COMPUTED_VALUE"""),"Gardu") -> Gardu | N25: =IFERROR(__xludf.DUMMYFUNCTION("""COMPUTED_VALUE"""),"CLD") -> CLD | O25: =IFERROR(__xludf.DUMMYFUNCTION("""COMPUTED_VALUE"""),"PEMBANDING SEJENIS") -> PEMBANDING SEJENIS | P25: =IFERROR(__xludf.DUMMYFUNCTION("""COMPUTED_VALUE"""),"KONEKTOR/JUMPER") -> KONEKTOR/JUMPER | Q25: =IFERROR(__xludf.DUMMYFUNCTION("""COMPUTED_VALUE"""),26.0) -> 26 | R25: =IFERROR(__xludf.DUMMYFUNCTION("""COMPUTED_VALUE"""),25.0) -> 25 | S25: =IFERROR(__xludf.DUMMYFUNCTION("""COMPUTED_VALUE"""),26.0) -> 26 | U25: =IFERROR(__xludf.DUMMYFUNCTION("""COMPUTED_VALUE"""),"BAIK") -> BAIK | V25: =IFERROR(__xludf.DUMMYFUNCTION("""COMPUTED_VALUE"""),"Tidak Ada") -> Tidak Ada | AC25: =IFERROR(__xludf.DUMMYFUNCTION("""COMPUTED_VALUE"""),"INSPEKSI SUTM - T2_Images/9e60e4ac.FOTO.075013.jpg") -> INSPEKSI SUTM - T2_Images/9e60e4ac.FOTO.075013.jpg | AF25: =IFERROR(__xludf.DUMMYFUNCTION("""COMPUTED_VALUE"""),"BELUM") -> BELUM | AG25: =IFERROR(__xludf.DUMMYFUNCTION("""COMPUTED_VALUE"""),46031.0) -> 46031
A26: =IFERROR(__xludf.DUMMYFUNCTION("""COMPUTED_VALUE"""),"e2037199") -> e2037199 | B26: =IFERROR(__xludf.DUMMYFUNCTION("""COMPUTED_VALUE"""),46031.82561342593) -> 46031.826 | C26: =IFERROR(__xludf.DUMMYFUNCTION("""COMPUTED_VALUE"""),"-6.899183, 107.641113") -> -6.899183, 107.641113 | D26: =IFERROR(__xludf.DUMMYFUNCTION("""COMPUTED_VALUE"""),"Sandi angga") -> Sandi angga | E26: =IFERROR(__xludf.DUMMYFUNCTION("""COMPUTED_VALUE"""),"BANDUNG") -> BANDUNG | F26: =IFERROR(__xludf.DUMMYFUNCTION("""COMPUTED_VALUE"""),"BANDUNG TIMUR") -> BANDUNG TIMUR | G26: =IFERROR(__xludf.DUMMYFUNCTION("""COMPUTED_VALUE"""),"KIARACONDONG") -> KIARACONDONG | H26: =IFERROR(__xludf.DUMMYFUNCTION("""COMPUTED_VALUE"""),"KPO") -> KPO | I26: =IFERROR(__xludf.DUMMYFUNCTION("""COMPUTED_VALUE"""),"LBS BKNA-RAT") -> LBS BKNA-RAT | J26: =IFERROR(__xludf.DUMMYFUNCTION("""COMPUTED_VALUE"""),"ZONA 2") -> ZONA 2 | K26: =IFERROR(__xludf.DUMMYFUNCTION("""COMPUTED_VALUE"""),"041L017") -> 041L017 | L26: =IFERROR(__xludf.DUMMYFUNCTION("""COMPUTED_VALUE"""),"TM - 14B/H (Akhir)") -> TM - 14B/H (Akhir) | M26: =IFERROR(__xludf.DUMMYFUNCTION("""COMPUTED_VALUE"""),"Tidak Ada") -> Tidak Ada | O26: =IFERROR(__xludf.DUMMYFUNCTION("""COMPUTED_VALUE"""),"PEMBANDING SEJENIS") -> PEMBANDING SEJENIS | P26: =IFERROR(__xludf.DUMMYFUNCTION("""COMPUTED_VALUE"""),"TERMINASI") -> TERMINASI | Q26: =IFERROR(__xludf.DUMMYFUNCTION("""COMPUTED_VALUE"""),24.0) -> 24 | R26: =IFERROR(__xludf.DUMMYFUNCTION("""COMPUTED_VALUE"""),24.0) -> 24 | S26: =IFERROR(__xludf.DUMMYFUNCTION("""COMPUTED_VALUE"""),24.0) -> 24 | U26: =IFERROR(__xludf.DUMMYFUNCTION("""COMPUTED_VALUE"""),"BAIK") -> BAIK | V26: =IFERROR(__xludf.DUMMYFUNCTION("""COMPUTED_VALUE"""),"Tidak Ada") -> Tidak Ada | AC26: =IFERROR(__xludf.DUMMYFUNCTION("""COMPUTED_VALUE"""),"INSPEKSI SUTM - T2_Images/e2037199.FOTO.075144.jpg") -> INSPEKSI SUTM - T2_Images/e2037199.FOTO.075144.jpg | AF26: =IFERROR(__xludf.DUMMYFUNCTION("""COMPUTED_VALUE"""),"BELUM") -> BELUM | AG26: =IFERROR(__xludf.DUMMYFUNCTION("""COMPUTED_VALUE"""),46031.0) -> 46031
A27: =IFERROR(__xludf.DUMMYFUNCTION("""COMPUTED_VALUE"""),"53af7c37") -> 53af7c37 | B27: =IFERROR(__xludf.DUMMYFUNCTION("""COMPUTED_VALUE"""),46031.910844907405) -> 46031.911 | C27: =IFERROR(__xludf.DUMMYFUNCTION("""COMPUTED_VALUE"""),"-6.899141, 107.641137") -> -6.899141, 107.641137 | D27: =IFERROR(__xludf.DUMMYFUNCTION("""COMPUTED_VALUE"""),"Sandi angga") -> Sandi angga | E27: =IFERROR(__xludf.DUMMYFUNCTION("""COMPUTED_VALUE"""),"BANDUNG") -> BANDUNG | F27: =IFERROR(__xludf.DUMMYFUNCTION("""COMPUTED_VALUE"""),"BANDUNG TIMUR") -> BANDUNG TIMUR | G27: =IFERROR(__xludf.DUMMYFUNCTION("""COMPUTED_VALUE"""),"KIARACONDONG") -> KIARACONDONG | H27: =IFERROR(__xludf.DUMMYFUNCTION("""COMPUTED_VALUE"""),"KPO") -> KPO | I27: =IFERROR(__xludf.DUMMYFUNCTION("""COMPUTED_VALUE"""),"LBS BKNA-RAT") -> LBS BKNA-RAT | J27: =IFERROR(__xludf.DUMMYFUNCTION("""COMPUTED_VALUE"""),"ZONA 2") -> ZONA 2 | K27: =IFERROR(__xludf.DUMMYFUNCTION("""COMPUTED_VALUE"""),"049") -> 049 | L27: =IFERROR(__xludf.DUMMYFUNCTION("""COMPUTED_VALUE"""),"TM - 4B/H (Afspan)") -> TM - 4B/H (Afspan) | M27: =IFERROR(__xludf.DUMMYFUNCTION("""COMPUTED_VALUE"""),"Tidak Ada") -> Tidak Ada | O27: =IFERROR(__xludf.DUMMYFUNCTION("""COMPUTED_VALUE"""),"PEMBANDING SEJENIS") -> PEMBANDING SEJENIS | P27: =IFERROR(__xludf.DUMMYFUNCTION("""COMPUTED_VALUE"""),"KONEKTOR/JUMPER") -> KONEKTOR/JUMPER | Q27: =IFERROR(__xludf.DUMMYFUNCTION("""COMPUTED_VALUE"""),24.0) -> 24 | R27: =IFERROR(__xludf.DUMMYFUNCTION("""COMPUTED_VALUE"""),23.0) -> 23 | S27: =IFERROR(__xludf.DUMMYFUNCTION("""COMPUTED_VALUE"""),24.0) -> 24 | U27: =IFERROR(__xludf.DUMMYFUNCTION("""COMPUTED_VALUE"""),"BAIK") -> BAIK | V27: =IFERROR(__xludf.DUMMYFUNCTION("""COMPUTED_VALUE"""),"Tidak Ada") -> Tidak Ada | AC27: =IFERROR(__xludf.DUMMYFUNCTION("""COMPUTED_VALUE"""),"INSPEKSI SUTM - T2_Images/53af7c37.FOTO.145233.jpg") -> INSPEKSI SUTM - T2_Images/53af7c37.FOTO.145233.jpg | AF27: =IFERROR(__xludf.DUMMYFUNCTION("""COMPUTED_VALUE"""),"BELUM") -> BELUM | AG27: =IFERROR(__xludf.DUMMYFUNCTION("""COMPUTED_VALUE"""),46031.0) -> 46031
A28: =IFERROR(__xludf.DUMMYFUNCTION("""COMPUTED_VALUE"""),"046b84f0") -> 046b84f0 | B28: =IFERROR(__xludf.DUMMYFUNCTION("""COMPUTED_VALUE"""),46031.91165509259) -> 46031.912 | C28: =IFERROR(__xludf.DUMMYFUNCTION("""COMPUTED_VALUE"""),"-6.899128, 107.641144") -> -6.899128, 107.641144 | D28: =IFERROR(__xludf.DUMMYFUNCTION("""COMPUTED_VALUE"""),"Sandi angga") -> Sandi angga | E28: =IFERROR(__xludf.DUMMYFUNCTION("""COMPUTED_VALUE"""),"BANDUNG") -> BANDUNG | F28: =IFERROR(__xludf.DUMMYFUNCTION("""COMPUTED_VALUE"""),"BANDUNG TIMUR") -> BANDUNG TIMUR | G28: =IFERROR(__xludf.DUMMYFUNCTION("""COMPUTED_VALUE"""),"KIARACONDONG") -> KIARACONDONG | H28: =IFERROR(__xludf.DUMMYFUNCTION("""COMPUTED_VALUE"""),"KPO") -> KPO | I28: =IFERROR(__xludf.DUMMYFUNCTION("""COMPUTED_VALUE"""),"LBS BKNA-RAT") -> LBS BKNA-RAT | J28: =IFERROR(__xludf.DUMMYFUNCTION("""COMPUTED_VALUE"""),"ZONA 2") -> ZONA 2 | K28: =IFERROR(__xludf.DUMMYFUNCTION("""COMPUTED_VALUE"""),"052") -> 052 | L28: =IFERROR(__xludf.DUMMYFUNCTION("""COMPUTED_VALUE"""),"TM - 13B/H (Kabel Naik Pada Tiang Tumpu)") -> TM - 13B/H (Kabel Naik Pada Tiang Tumpu) | M28: =IFERROR(__xludf.DUMMYFUNCTION("""COMPUTED_VALUE"""),"Gardu") -> Gardu | N28: =IFERROR(__xludf.DUMMYFUNCTION("""COMPUTED_VALUE"""),"BKR") -> BKR | O28: =IFERROR(__xludf.DUMMYFUNCTION("""COMPUTED_VALUE"""),"PEMBANDING SEJENIS") -> PEMBANDING SEJENIS | P28: =IFERROR(__xludf.DUMMYFUNCTION("""COMPUTED_VALUE"""),"TERMINASI") -> TERMINASI | Q28: =IFERROR(__xludf.DUMMYFUNCTION("""COMPUTED_VALUE"""),23.0) -> 23 | R28: =IFERROR(__xludf.DUMMYFUNCTION("""COMPUTED_VALUE"""),22.0) -> 22 | S28: =IFERROR(__xludf.DUMMYFUNCTION("""COMPUTED_VALUE"""),21.0) -> 21 | U28: =IFERROR(__xludf.DUMMYFUNCTION("""COMPUTED_VALUE"""),"BAIK") -> BAIK | V28: =IFERROR(__xludf.DUMMYFUNCTION("""COMPUTED_VALUE"""),"Tidak Ada") -> Tidak Ada | AC28: =IFERROR(__xludf.DUMMYFUNCTION("""COMPUTED_VALUE"""),"INSPEKSI SUTM - T2_Images/046b84f0.FOTO.145339.jpg") -> INSPEKSI SUTM - T2_Images/046b84f0.FOTO.145339.jpg | AF28: =IFERROR(__xludf.DUMMYFUNCTION("""COMPUTED_VALUE"""),"BELUM") -> BELUM | AG28: =IFERROR(__xludf.DUMMYFUNCTION("""COMPUTED_VALUE"""),46031.0) -> 46031
A29: =IFERROR(__xludf.DUMMYFUNCTION("""COMPUTED_VALUE"""),"abac2e3b") -> abac2e3b | B29: =IFERROR(__xludf.DUMMYFUNCTION("""COMPUTED_VALUE"""),46031.91226851852) -> 46031.912 | C29: =IFERROR(__xludf.DUMMYFUNCTION("""COMPUTED_VALUE"""),"-6.899127, 107.641139") -> -6.899127, 107.641139 | D29: =IFERROR(__xludf.DUMMYFUNCTION("""COMPUTED_VALUE"""),"Sandi angga") -> Sandi angga | E29: =IFERROR(__xludf.DUMMYFUNCTION("""COMPUTED_VALUE"""),"BANDUNG") -> BANDUNG | F29: =IFERROR(__xludf.DUMMYFUNCTION("""COMPUTED_VALUE"""),"BANDUNG TIMUR") -> BANDUNG TIMUR | G29: =IFERROR(__xludf.DUMMYFUNCTION("""COMPUTED_VALUE"""),"KIARACONDONG") -> KIARACONDONG | H29: =IFERROR(__xludf.DUMMYFUNCTION("""COMPUTED_VALUE"""),"KPO") -> KPO | I29: =IFERROR(__xludf.DUMMYFUNCTION("""COMPUTED_VALUE"""),"LBS BKNA-RAT") -> LBS BKNA-RAT | J29: =IFERROR(__xludf.DUMMYFUNCTION("""COMPUTED_VALUE"""),"ZONA 2") -> ZONA 2 | K29: =IFERROR(__xludf.DUMMYFUNCTION("""COMPUTED_VALUE"""),"053") -> 053 | L29: =IFERROR(__xludf.DUMMYFUNCTION("""COMPUTED_VALUE"""),"TM - 1B/H (Tumpu)") -> TM - 1B/H (Tumpu) | M29: =IFERROR(__xludf.DUMMYFUNCTION("""COMPUTED_VALUE"""),"Tidak Ada") -> Tidak Ada | O29: =IFERROR(__xludf.DUMMYFUNCTION("""COMPUTED_VALUE"""),"PEMBANDING SEJENIS") -> PEMBANDING SEJENIS | P29: =IFERROR(__xludf.DUMMYFUNCTION("""COMPUTED_VALUE"""),"KONEKTOR/JUMPER") -> KONEKTOR/JUMPER | Q29: =IFERROR(__xludf.DUMMYFUNCTION("""COMPUTED_VALUE"""),23.0) -> 23 | R29: =IFERROR(__xludf.DUMMYFUNCTION("""COMPUTED_VALUE"""),24.0) -> 24 | S29: =IFERROR(__xludf.DUMMYFUNCTION("""COMPUTED_VALUE"""),23.0) -> 23 | U29: =IFERROR(__xludf.DUMMYFUNCTION("""COMPUTED_VALUE"""),"BAIK") -> BAIK | V29: =IFERROR(__xludf.DUMMYFUNCTION("""COMPUTED_VALUE"""),"Tidak Ada") -> Tidak Ada | AC29: =IFERROR(__xludf.DUMMYFUNCTION("""COMPUTED_VALUE"""),"INSPEKSI SUTM - T2_Images/abac2e3b.FOTO.145449.jpg") -> INSPEKSI SUTM - T2_Images/abac2e3b.FOTO.145449.jpg | AF29: =IFERROR(__xludf.DUMMYFUNCTION("""COMPUTED_VALUE"""),"BELUM") -> BELUM | AG29: =IFERROR(__xludf.DUMMYFUNCTION("""COMPUTED_VALUE"""),46031.0) -> 46031
